Workbook

Sheet Dashboard
A1: MILLSTADT EMS DISTRICT — BUDGET PLANNER | J1: SCENARIO | K1: =Scenarios!B3 -> AVERAGE
A4: DISTRICT & REVENUE LEVERS | E4: TOTAL PROJECTED REVENUE | H4: TOTAL ANNUAL EXPENSES | K4: SURPLUS / (SHORTFALL)
A5: Proposed District EAV | B5: 350704800 | C5: $ | E5: =Budget!C12 -> 2558886 | H5: =Budget!C38 -> 2035252.2 | K5: =Budget!C40 -> 523633.81
A6: Levy Rate | B6: 0.003 | C6: %
A7: Collection Factor | B7: 0.98 | C7: % | E7: BREAK-EVEN LEVY RATE | H7: TAX ON REFERENCE HOME / YR | K7: TAX / MONTH
A8: Annual Call Volume | B8: 879 | C8: calls / yr | D8: ="Total incl. transfers: "&TEXT(B8+'Transfer Division'!H10,"#,##0")&" runs / yr" -> Total incl. transfers: 2,379 runs / yr | E8: =IF(B5*B7=0,0,(Budget!C38-Budget!C6-SUM(Budget!C7:C11)-'Transfer Division'!H38)/(B5*B7)) -> 0.0014764388 | H8: =B28*B29*B6 -> 300 | K8: =(B28*B29*B6)/12 -> 25
A9: Transport Rate | B9: 0.6291 | C9: % of calls
A10: Net Collection per Transport | B10: 525 | C10: $ / transport
A11: Billing Company Fee | B11: 0.055 | C11: % of billing revenue
A13: STAFFING LEVERS
A14: Chiefs | B14: =Scenarios!F56 -> 2 | C14: → set on Scenarios tab
A15: Chief Salary | B15: =Scenarios!F8 -> 120000 | C15: → set on Scenarios tab
A16: Office Manager | B16: =Scenarios!F57 -> 0 | C16: → set on Scenarios tab
A17: Office Manager Salary | B17: =Scenarios!F9 -> 50000 | C17: → set on Scenarios tab
A18: Full-Time Paramedics | B18: =Scenarios!F58 -> 3 | C18: → set on Scenarios tab
A19: Paramedic Hourly Rate | B19: =Scenarios!F10 -> 21 | C19: → set on Scenarios tab
A20: Full-Time EMTs | B20: =Scenarios!F59 -> 3 | C20: → set on Scenarios tab
A21: EMT Hourly Rate | B21: =Scenarios!F11 -> 17 | C21: → set on Scenarios tab
A22: Regular Hours per Field Employee | B22: 2080 | C22: hrs / yr
A23: Scheduled OT Hours | B23: 832 | C23: hrs / yr
A24: Training Hours | B24: 0 | C24: hrs / yr
A25: Unscheduled OT Hours (total) | B25: 1000 | C25: hrs / yr
A27: HOMEOWNER REFERENCE
A28: Reference Home Market Value | B28: 300000 | C28: $
A29: Assessment Factor | B29: 0.33333333 | C29: % of market value
A32: LEVY RATE SCENARIOS — WHICH RATE PAYS THE BILLS?
A33: RATE | B33: LEVY REVENUE | C33: TOTAL REVENUE | D33: ANNUAL EXPENSES | E33: SURPLUS / (SHORTFALL) | F33: RESULT | G33: RATE (EDIT)
A34: =TEXT(G34,"0.00%") -> 0.20% | B34: =$B$5*G34*$B$7 -> 687381.41 | C34: =B34+Budget!$C$6+SUM(Budget!$C$7:$C$11)+'Transfer Division'!$H$38 -> 2215195.3 | D34: =Budget!$C$38 -> 2035252.2 | E34: =C34-D34 -> 179943.11 | F34: =IF(E34>=0,"Fully Funds Budget","Funding Gap") -> Fully Funds Budget | G34: 0.002
A35: =TEXT(G35,"0.00%") -> 0.25% | B35: =$B$5*G35*$B$7 -> 859226.76 | C35: =B35+Budget!$C$6+SUM(Budget!$C$7:$C$11)+'Transfer Division'!$H$38 -> 2387040.7 | D35: =Budget!$C$38 -> 2035252.2 | E35: =C35-D35 -> 351788.46 | F35: =IF(E35>=0,"Fully Funds Budget","Funding Gap") -> Fully Funds Budget | G35: 0.0025
A36: =TEXT(G36,"0.00%") -> 0.30% | B36: =$B$5*G36*$B$7 -> 1031072.1 | C36: =B36+Budget!$C$6+SUM(Budget!$C$7:$C$11)+'Transfer Division'!$H$38 -> 2558886 | D36: =Budget!$C$38 -> 2035252.2 | E36: =C36-D36 -> 523633.81 | F36: =IF(E36>=0,"Fully Funds Budget","Funding Gap") -> Fully Funds Budget | G36: 0.003
A37: =TEXT(G37,"0.00%") -> 0.35% | B37: =$B$5*G37*$B$7 -> 1202917.5 | C37: =B37+Budget!$C$6+SUM(Budget!$C$7:$C$11)+'Transfer Division'!$H$38 -> 2730731.4 | D37: =Budget!$C$38 -> 2035252.2 | E37: =C37-D37 -> 695479.17 | F37: =IF(E37>=0,"Fully Funds Budget","Funding Gap") -> Fully Funds Budget | G37: 0.0035
A38: =TEXT(G38,"0.00%") -> 0.40% | B38: =$B$5*G38*$B$7 -> 1374762.8 | C38: =B38+Budget!$C$6+SUM(Budget!$C$7:$C$11)+'Transfer Division'!$H$38 -> 2902576.7 | D38: =Budget!$C$38 -> 2035252.2 | E38: =C38-D38 -> 867324.52 | F38: =IF(E38>=0,"Fully Funds Budget","Funding Gap") -> Fully Funds Budget | G38: 0.004
A41: ANNUAL PROPERTY TAX BY HOME VALUE
A42: HOME MARKET VALUE | B42: =TEXT(G34,"0.00%") -> 0.20% | C42: =TEXT(G35,"0.00%") -> 0.25% | D42: =TEXT(G36,"0.00%") -> 0.30% | E42: =TEXT(G37,"0.00%") -> 0.35% | F42: =TEXT(G38,"0.00%") -> 0.40%
A43: 100000 | B43: =$A43*$B$29*G$34 -> 66.666667 | C43: =$A43*$B$29*G$35 -> 83.333333 | D43: =$A43*$B$29*G$36 -> 100 | E43: =$A43*$B$29*G$37 -> 116.66667 | F43: =$A43*$B$29*G$38 -> 133.33333
A44: 200000 | B44: =$A44*$B$29*G$34 -> 133.33333 | C44: =$A44*$B$29*G$35 -> 166.66667 | D44: =$A44*$B$29*G$36 -> 200 | E44: =$A44*$B$29*G$37 -> 233.33333 | F44: =$A44*$B$29*G$38 -> 266.66667
A45: 300000 | B45: =$A45*$B$29*G$34 -> 200 | C45: =$A45*$B$29*G$35 -> 250 | D45: =$A45*$B$29*G$36 -> 300 | E45: =$A45*$B$29*G$37 -> 350 | F45: =$A45*$B$29*G$38 -> 400
A46: 400000 | B46: =$A46*$B$29*G$34 -> 266.66667 | C46: =$A46*$B$29*G$35 -> 333.33333 | D46: =$A46*$B$29*G$36 -> 400 | E46: =$A46*$B$29*G$37 -> 466.66667 | F46: =$A46*$B$29*G$38 -> 533.33333
A47: 500000 | B47: =$A47*$B$29*G$34 -> 333.33333 | C47: =$A47*$B$29*G$35 -> 416.66667 | D47: =$A47*$B$29*G$36 -> 500 | E47: =$A47*$B$29*G$37 -> 583.33333 | F47: =$A47*$B$29*G$38 -> 666.66667
A50: EXPENSE MIX (feeds the chart)
...

Sheet Budget
A1: MILLSTADT EMS DISTRICT — ANNUAL REFERENDUM BUDGET
A2: ="Annual budget at the selected "&TEXT(Dashboard!B6,"0.00%")&" levy rate · Scenario: "&Dashboard!K1&" · This page updates itself." -> Annual budget at the selected 0.30% levy rate · Scenario: AVERAGE · This page updates itself.
A4: PROJECTED REVENUE
A5: Property Tax Levy Revenue | B5: EAV × levy rate × collection factor | C5: =Dashboard!B5*Dashboard!B6*Dashboard!B7 -> 1031072.1
A6: EMS Billing Revenue | B6: Calls × transport rate × net collection | C6: =Dashboard!B8*Dashboard!B9*Dashboard!B10 -> 290313.92
A7: Current Ambulance-Fund Revenue | C7: 0
A8: Interest Income | C8: 0
A9: Donations | C9: 0
A10: Fundraising | C10: 0
A11: Miscellaneous Revenue | C11: 0
A12: TOTAL PROJECTED REVENUE | C12: =SUM(C5:C11)+'Transfer Division'!H38 -> 2558886
A14: PERSONNEL
A15: Full-Time Payroll | B15: Salaries, wages, OT, holiday & training pay | C15: =Details!E15 -> 651492
A16: Employer Costs | B16: FICA, IMRF, unemployment, work comp, uniforms | C16: =Details!E26 -> 182661.88
A17: Part-Time Staffing | B17: 8–10 employee relief pool | C17: =Details!E37 -> 88578.5
A18: Employee Benefits | B18: Medical, dental, vision, life, disability | C18: =Details!E49 -> 213500
A19: TOTAL PERSONNEL | C19: =SUM(C15:C18) -> 1136232.4
A21: OPERATIONS
A22: Medical Supplies & Patient Care | C22: =SUMIF(Details!$A$74:$A$116,A22,Details!$H$74:$H$116) -> 35350
A23: Equipment Maintenance | C23: =SUMIF(Details!$A$74:$A$116,A23,Details!$H$74:$H$116) -> 9003.14
A24: Fleet | C24: =SUMIF(Details!$A$74:$A$116,A24,Details!$H$74:$H$116) -> 55100
A25: Facilities & Utilities | C25: =SUMIF(Details!$A$74:$A$116,A25,Details!$H$74:$H$116) -> 8550
A26: Communications & Dispatch | C26: =SUMIF(Details!$A$74:$A$116,A26,Details!$H$74:$H$116) -> 15490
A27: Professional Services & Billing | C27: =SUMIF(Details!$A$74:$A$116,A27,Details!$H$74:$H$116) -> 23967.266
A28: Technology | C28: =SUMIF(Details!$A$74:$A$116,A28,Details!$H$74:$H$116) -> 8994
A29: Administration | C29: =SUMIF(Details!$A$74:$A$116,A29,Details!$H$74:$H$116) -> 900
A30: TOTAL OPERATIONS | C30: =SUM(C22:C29) -> 157354.41
A32: DEBT & OBLIGATIONS
A33: Debt Service | B33: Current loan payments (see ON/OFF per loan) | C33: =Details!H127 -> 97801.08
A34: Past-Due Bill Payments | B34: Catch-up plan — switched OFF right now | C34: =Details!E134 -> 0
A35: Capital Reserves — Startup | B35: Future ambulances & equipment | C35: =Details!H150 -> 0
A36: TOTAL DEBT & OBLIGATIONS | C36: =SUM(C33:C35) -> 97801.08
A38: TOTAL ANNUAL EXPENSES | C38: =C19+C30+C36+'Transfer Division'!H39 -> 2035252.2
A40: ANNUAL SURPLUS / (SHORTFALL) | C40: =C12-C38 -> 523633.81
A43: WHAT IT COSTS A HOMEOWNER
A44: ="Annual tax on a "&TEXT(Dashboard!B28,"$#,##0")&" home at "&TEXT(Dashboard!B6,"0.00%") -> Annual tax on a $300,000 home at 0.30% | C44: =Dashboard!B28*Dashboard!B29*Dashboard!B6 -> 300
A45: That works out per month to | C45: =C44/12 -> 25
A47: TRANSFER DIVISION (counts only while switched ON on its tab)
A48: Transfer Division Revenue | C48: ='Transfer Division'!H38 -> 1237500
A49: Transfer Division Expenses | C49: ='Transfer Division'!H39 -> 643864.36
...

Sheet Details
A1: MILLSTADT EMS DISTRICT — BUDGET DETAILS
A2: Gold cells are editable · green/gray cells are ON/OFF switches (click the cell, then the arrow) · everything rolls up automatically.
A4: FULL-TIME PAYROLL
A5: ITEM | B5: BASIS | C5: EMPLOYEES / HOURS | D5: RATE | E5: ANNUAL COST
A6: Chief Salaries | B6: Count × salary | C6: =Dashboard!B14 -> 2 | D6: =Dashboard!B15 -> 120000 | E6: =C6*D6 -> 240000
A7: Office Manager | B7: Count × salary | C7: =Dashboard!B16 -> 0 | D7: =Dashboard!B17 -> 50000 | E7: =C7*D7 -> 0
A8: Full-Time Paramedic Scheduled Wages | B8: Regular + scheduled OT @ 1.5× | C8: =Dashboard!B18 -> 3 | D8: =Dashboard!B19 -> 21 | E8: =C8*((Dashboard!B22*D8)+(Dashboard!B23*D8*1.5)) -> 209664
A9: Full-Time EMT Scheduled Wages | B9: Regular + scheduled OT @ 1.5× | C9: =Dashboard!B20 -> 3 | D9: =Dashboard!B21 -> 17 | E9: =C9*((Dashboard!B22*D9)+(Dashboard!B23*D9*1.5)) -> 169728
A10: Holiday Pay | B10: TOTAL HOLIDAY PAY from the table below | E10: =G69 -> 0
A11: Birthday Bonuses | B11: Birthday Bonus row in the table below | E11: =G70 -> 600
A12: Unscheduled Overtime | B12: Hours × paramedic rate × 1.5 | C12: =Dashboard!B25 -> 1000 | D12: =Dashboard!B19*1.5 -> 31.5 | E12: =C12*D12 -> 31500
A13: Paramedic Training Pay | B13: Medics × training hrs × rate | C13: =Dashboard!B18*Dashboard!B24 -> 0 | D13: =Dashboard!B19 -> 21 | E13: =C13*D13 -> 0
A14: EMT Training Pay | B14: EMTs × training hrs × rate | C14: =Dashboard!B20*Dashboard!B24 -> 0 | D14: =Dashboard!B21 -> 17 | E14: =C14*D14 -> 0
A15: TOTAL FULL-TIME PAYROLL | E15: =SUM(E6:E14) -> 651492
A17: EMPLOYER COSTS
A18: ITEM | B18: BASIS / WAGE BASE | C18: EMPLOYEES | D18: RATE | E18: ANNUAL COST
A19: Social Security | B19: % of payroll | D19: 0.062 | E19: =$E$15*D19 -> 40392.504
A20: Medicare | B20: % of payroll | D20: 0.0145 | E20: =$E$15*D20 -> 9446.634
A21: IMRF | B21: % of payroll | D21: 0.095 | E21: =$E$15*D21 -> 61891.74
A22: Illinois Unemployment | B22: 14250 | C22: =Dashboard!B14+Dashboard!B16+Dashboard!B18+Dashboard!B20 -> 8 | D22: 0.0335 | E22: =B22*C22*D22 -> 3819
A23: Workers' Compensation | B23: Annual premium | E23: 47612
A24: Payroll Processing | B24: Annual | E24: 10500
A25: Uniform Allowances | B25: 1500/yr chiefs 1000/yr employees | C25: =Dashboard!B14+Dashboard!B18+Dashboard!B20 -> 8 | E25: =(Dashboard!B14*1500)+((Dashboard!B18+Dashboard!B20)*1000) -> 9000
A26: TOTAL EMPLOYER COSTS | E26: =SUM(E19:E25) -> 182661.88
A28: PART-TIME STAFFING — RELIEF POOL
A29: ITEM | B29: NOTE | E29: ANNUAL COST
A30: Base Part-Time Wages | E30: =Scenarios!F14 -> 69000
A31: Relief / Scheduling Reserve | E31: =Scenarios!F15 -> 0
A32: Employer FICA & Medicare | E32: =Scenarios!F16 -> 5278.5
A33: Unemployment & Payroll Contingency | E33: =Scenarios!F17 -> 6300
A34: Training, Credentialing & Meetings | E34: =Scenarios!F18 -> 3000
A35: Uniforms & Onboarding | E35: =Scenarios!F19 -> 5000
A36: Vacancy / Call-Back Reserve | E36: =Scenarios!F20 -> 0
A37: TOTAL PART-TIME STAFFING | E37: =SUM(E30:E36) -> 88578.5
A39: EMPLOYEE BENEFITS — FULL-TIME
A40: ITEM | B40: POLICY | E40: ANNUAL COST
A41: Medical Insurance | E41: =Scenarios!F24 -> 170000
A42: Dental Insurance | E42: =Scenarios!F25 -> 11000
A43: Vision Insurance | E43: =Scenarios!F26 -> 3500
A44: Life & AD&D | E44: =Scenarios!F27 -> 5000
...

Sheet Scenarios
A1: SCENARIO SETTINGS — BARE MINIMUM / AVERAGE / IDEAL
A2: All three columns are GOLD — fill them out however you want. The Dashboard dropdown picks which column the live budget uses; the ACTIVE column shows what's in play right now. | H2: =IF(B3="BARE MINIMUM",1,IF(B3="IDEAL",3,2)) -> 2
A3: ACTIVE SCENARIO | B3: AVERAGE | C3: ◀ pick it HERE — the whole workbook flips (Dashboard mirrors this)
A6: LEVER | B6: UNIT | C6: BARE MINIMUM | D6: AVERAGE | E6: IDEAL | F6: ACTIVE (IN USE)
A7: FULL-TIME WAGES
A8: Chief Salary | B8: $ / yr | C8: 120000 | D8: 120000 | E8: 130000 | F8: =CHOOSE($H$2,C8,D8,E8) -> 120000
A9: Office Manager Salary | B9: $ / yr | C9: 45000 | D9: 50000 | E9: 55000 | F9: =CHOOSE($H$2,C9,D9,E9) -> 50000
A10: Paramedic Hourly Rate | B10: $ / hr | C10: 20 | D10: 21 | E10: 25 | F10: =CHOOSE($H$2,C10,D10,E10) -> 21
A11: EMT Hourly Rate | B11: $ / hr | C11: 16 | D11: 17 | E11: 20 | F11: =CHOOSE($H$2,C11,D11,E11) -> 17
A13: PART-TIME STAFFING
A14: Base Part-Time Wages | B14: $ / yr | C14: 40000 | D14: 69000 | E14: 85000 | F14: =CHOOSE($H$2,C14,D14,E14) -> 69000
A15: Relief / Scheduling Reserve | B15: $ / yr | C15: 0 | D15: 0 | E15: 0 | F15: =CHOOSE($H$2,C15,D15,E15) -> 0
A16: Employer FICA & Medicare | B16: $ / yr | C16: =(C14+C15)*(Details!$D$19+Details!$D$20) -> 3060 | D16: =(D14+D15)*(Details!$D$19+Details!$D$20) -> 5278.5 | E16: =(E14+E15)*(Details!$D$19+Details!$D$20) -> 6502.5 | F16: =CHOOSE($H$2,C16,D16,E16) -> 5278.5 | G16: Auto-calculates: 7.65% of PT wages above — no need to touch
A17: Unemployment & Payroll Contingency | B17: $ / yr | C17: 6300 | D17: 6300 | E17: 6300 | F17: =CHOOSE($H$2,C17,D17,E17) -> 6300
A18: Training, Credentialing & Meetings | B18: $ / yr | C18: 0 | D18: 3000 | E18: 6000 | F18: =CHOOSE($H$2,C18,D18,E18) -> 3000
A19: Uniforms & Onboarding | B19: $ / yr | C19: 5000 | D19: 5000 | E19: 5000 | F19: =CHOOSE($H$2,C19,D19,E19) -> 5000
A20: Vacancy / Call-Back Reserve | B20: $ / yr | C20: 0 | D20: 0 | E20: 0 | F20: =CHOOSE($H$2,C20,D20,E20) -> 0
A21: PART-TIME TOTAL | C21: =SUM(C14:C20) -> 54360 | D21: =SUM(D14:D20) -> 88578.5 | E21: =SUM(E14:E20) -> 108802.5 | F21: =SUM(F14:F20) -> 88578.5
A23: EMPLOYEE BENEFITS
A24: Medical Insurance | B24: $ / yr | C24: 100000 | D24: 170000 | E24: 300000 | F24: =CHOOSE($H$2,C24,D24,E24) -> 170000
A25: Dental Insurance | B25: $ / yr | C25: 6000 | D25: 11000 | E25: 20000 | F25: =CHOOSE($H$2,C25,D25,E25) -> 11000
A26: Vision Insurance | B26: $ / yr | C26: 2000 | D26: 3500 | E26: 7000 | F26: =CHOOSE($H$2,C26,D26,E26) -> 3500
A27: Life & AD&D | B27: $ / yr | C27: 1500 | D27: 5000 | E27: 15000 | F27: =CHOOSE($H$2,C27,D27,E27) -> 5000
A28: Short- and Long-Term Disability | B28: $ / yr | C28: 1500 | D28: 10000 | E28: 22000 | F28: =CHOOSE($H$2,C28,D28,E28) -> 10000
A29: Employee Assistance / Behavioral Health | B29: $ / yr | C29: 1000 | D29: 1500 | E29: 5000 | F29: =CHOOSE($H$2,C29,D29,E29) -> 1500
A30: COBRA & Benefits Administration | B30: $ / yr | C30: 4000 | D30: 7000 | E30: 10000 | F30: =CHOOSE($H$2,C30,D30,E30) -> 7000
A31: Renewal & Enrollment Contingency | B31: $ / yr | C31: 4000 | D31: 5500 | E31: 15000 | F31: =CHOOSE($H$2,C31,D31,E31) -> 5500
A32: BENEFITS TOTAL | C32: =SUM(C24:C31) -> 120000 | D32: =SUM(D24:D31) -> 213500 | E32: =SUM(E24:E31) -> 394000 | F32: =SUM(F24:F31) -> 213500
A34: HOLIDAY & BIRTHDAY
A35: Holiday Extra Pay per Hour | B35: $ / hr | C35: 0 | D35: 1 | E35: 2 | F35: =CHOOSE($H$2,C35,D35,E35) -> 1
A36: Birthday Bonus per Employee | B36: $ / employee | C36: 0 | D36: 100 | E36: 200 | F36: =CHOOSE($H$2,C36,D36,E36) -> 100
A38: SIDE-BY-SIDE — WHAT EACH SCENARIO DOES TO THE BUDGET (live) | H38: =Dashboard!B22+Dashboard!B23*1.5+Dashboard!B24 -> 3328
A39: RESULT | C39: BARE MINIMUM | D39: AVERAGE | E39: IDEAL | H39: =IF(Details!G51="OFF",0,SUMPRODUCT((Details!B53:B68="ON")*Details!C53:C68*Details!D53:D68*Details!E53:E68)) -> 0
A40: Full-Time Payroll | C40: =C$56*C$8+C$57*C$9+(C$58*C$10+C$59*C$11)*$H$38+Dashboard!$B$25*C$10*1.5+$H$39*C$35+$H$40*(C$58+C$59)*C$36 -> 629424 | D40: =D$56*D$8+D$57*D$9+(D$58*D$10+D$59*D$11)*$H$38+Dashboard!$B$25*D$10*1.5+$H$39*D$35+$H$40*(D$58+D$59)*D$36 -> 651492 | E40: =E$56*E$8+E$57*E$9+(E$58*E$10+E$59*E$11)*$H$38+Dashboard!$B$25*E$10*1.5+$H$39*E$35+$H$40*(E$58+E$59)*E$36 -> 802980 | H40: =IF(Details!B70="OFF",0,1) -> 1
A41: Employer Costs | C41: =C40*(Details!$D$19+Details!$D$20+Details!$D$21)+Details!$B$22*(C$56+C$57+C$58+C$59)*Details!$D$22+Details!$E$23+Details!$E$24+(C$56*1500+(C$58+C$59)*1000) -> 178877.22 | D41: =D40*(Details!$D$19+Details!$D$20+Details!$D$21)+Details!$B$22*(D$56+D$57+D$58+D$59)*Details!$D$22+Details!$E$23+Details!$E$24+(D$56*1500+(D$58+D$59)*1000) -> 182661.88 | E41: =E40*(Details!$D$19+Details!$D$20+Details!$D$21)+Details!$B$22*(E$56+E$57+E$58+E$59)*Details!$D$22+Details!$E$23+Details!$E$24+(E$56*1500+(E$58+E$59)*1000) -> 209119.44
A42: Part-Time Staffing | C42: =C21 -> 54360 | D42: =D21 -> 88578.5 | E42: =E21 -> 108802.5
A43: Employee Benefits | C43: =C32 -> 120000 | D43: =D32 -> 213500 | E43: =E32 -> 394000
A44: TOTAL PERSONNEL | C44: =SUM(C40:C43) -> 982661.22 | D44: =SUM(D40:D43) -> 1136232.4 | E44: =SUM(E40:E43) -> 1514901.9
A45: Operations (at scenario line %) | C45: =SUMPRODUCT(Details!$J$74:$J$116,Details!$D$74:$D$116) -> 137704.41 | D45: =SUMPRODUCT(Details!$J$74:$J$116,Details!$E$74:$E$116) -> 157354.41 | E45: =SUMPRODUCT(Details!$J$74:$J$116,Details!$F$74:$F$116) -> 177804.41
A46: Debt & Obligations (same in all) | C46: =Budget!$C$36 -> 97801.08 | D46: =Budget!$C$36 -> 97801.08 | E46: =Budget!$C$36 -> 97801.08
...

Sheet Transfer Division
A1: TRANSFER DIVISION — ALL PART-TIME
A2: Pick a FLEET CONFIGURATION below — crews, wages and reimbursement all follow it. Only one configuration can be active. Nothing counts in the budget until the switch is ON.
A3: INCLUDE TRANSFER DIVISION IN BUDGET | B3: ON
A4: FLEET CONFIGURATION ▶ | B4: 2 Critical Care Trucks | E4: ◀ pick ONE — crews & reimbursement in the table at the bottom | H4: =IFERROR(MATCH($B$4,$A$45:$A$49,0),1) -> 4
A5: LEVER | B5: UNIT | C5: BARE MINIMUM | D5: AVERAGE | E5: IDEAL | G5: NOTES / SERVICE IMPACT
A6: TRANSFER REVENUE
A7: Transfer Runs per Year (your estimate) | B7: runs / yr | C7: 1500 | D7: 1500 | E7: 1500 | F7: =CHOOSE(Scenarios!$H$2,C7,D7,E7) -> 1500
A8: Net Collection per Transfer | B8: $ / run | C8: =INDEX($C$45:$C$49,$H$4) -> 825 | D8: =INDEX($C$45:$C$49,$H$4) -> 825 | E8: =INDEX($C$45:$C$49,$H$4) -> 825 | F8: =CHOOSE(Scenarios!$H$2,C8,D8,E8) -> 825 | G8: Comes from the configuration table below — ALS/CC configs reimburse higher
A9: Billing Company Fee | B9: % of transfer billing | C9: 0.055 | D9: 0.055 | E9: 0.055 | F9: =CHOOSE(Scenarios!$H$2,C9,D9,E9) -> 0.055
A10: Transfer Billing Revenue | B10: $ / yr | C10: =C7*C8 -> 1237500 | D10: =D7*D8 -> 1237500 | E10: =E7*E8 -> 1237500 | F10: =CHOOSE(Scenarios!$H$2,C10,D10,E10) -> 1237500 | H10: =IF($B$3="OFF",0,CHOOSE(Scenarios!$H$2,C7,D7,E7)) -> 1500
A11: Billing Company Cost | B11: $ / yr | C11: =C10*C9 -> 68062.5 | D11: =D10*D9 -> 68062.5 | E11: =E10*E9 -> 68062.5 | F11: =CHOOSE(Scenarios!$H$2,C11,D11,E11) -> 68062.5
A12: TRANSFER STAFFING — ALL PART-TIME · crew set by the configuration (2 trucks)
A13: Hours per Truck per Day | B13: hrs / day | C13: 10 | D13: 10 | E13: 10 | F13: =CHOOSE(Scenarios!$H$2,C13,D13,E13) -> 10
A14: Days per Week | B14: days / wk | C14: 5 | D14: 5 | E14: 5 | F14: =CHOOSE(Scenarios!$H$2,C14,D14,E14) -> 5
A15: Annual Hours per Truck | B15: hrs / yr | C15: =C13*C14*365/7 -> 2607.1429 | D15: =D13*D14*365/7 -> 2607.1429 | E15: =E13*E14*365/7 -> 2607.1429 | F15: =CHOOSE(Scenarios!$H$2,C15,D15,E15) -> 2607.1429
A16: Part-Time EMT Rate | B16: $ / hr | C16: 20 | D16: 26 | E16: 28 | F16: =CHOOSE(Scenarios!$H$2,C16,D16,E16) -> 26
A17: Part-Time Paramedic Rate | B17: $ / hr | C17: 24 | D17: 28 | E17: 30 | F17: =CHOOSE(Scenarios!$H$2,C17,D17,E17) -> 28
A18: Critical Care Provider Rate | B18: $ / hr | C18: 26 | D18: 30 | E18: 32 | F18: =CHOOSE(Scenarios!$H$2,C18,D18,E18) -> 30 | G18: PLACEHOLDER — set what you'd actually pay a critical care provider
A19: Crew Wages (whole fleet) | B19: $ / yr | C19: =C15*(CHOOSE($H$4,2,4,3,0,2)*C16+CHOOSE($H$4,2,0,1,2,1)*C17+CHOOSE($H$4,0,0,0,2,1)*C18) -> 260714.29 | D19: =D15*(CHOOSE($H$4,2,4,3,0,2)*D16+CHOOSE($H$4,2,0,1,2,1)*D17+CHOOSE($H$4,0,0,0,2,1)*D18) -> 302428.57 | E19: =E15*(CHOOSE($H$4,2,4,3,0,2)*E16+CHOOSE($H$4,2,0,1,2,1)*E17+CHOOSE($H$4,0,0,0,2,1)*E18) -> 323285.71 | F19: =CHOOSE(Scenarios!$H$2,C19,D19,E19) -> 302428.57 | G19: Per-truck hours × everyone on duty in the chosen configuration
A20: Overtime Allowance | B20: $ / yr | C20: 60000 | D20: 75000 | E20: 100000 | F20: =CHOOSE(Scenarios!$H$2,C20,D20,E20) -> 75000
A21: Employer FICA & Medicare | B21: $ / yr | C21: =(C19+C20)*(Details!$D$19+Details!$D$20) -> 24534.643 | D21: =(D19+D20)*(Details!$D$19+Details!$D$20) -> 28873.286 | E21: =(E19+E20)*(Details!$D$19+Details!$D$20) -> 32381.357 | F21: =CHOOSE(Scenarios!$H$2,C21,D21,E21) -> 28873.286
A22: Unemployment & Payroll Contingency | B22: $ / yr | C22: 12000 | D22: 15000 | E22: 20000 | F22: =CHOOSE(Scenarios!$H$2,C22,D22,E22) -> 15000
A23: Transfer PT Pool Size | B23: employees | C23: 25 | D23: 25 | E23: 25 | F23: =CHOOSE(Scenarios!$H$2,C23,D23,E23) -> 25
A24: Uniform Allowances ($300 each) | B24: $ / yr | C24: =C23*300 -> 7500 | D24: =D23*300 -> 7500 | E24: =E23*300 -> 7500 | F24: =CHOOSE(Scenarios!$H$2,C24,D24,E24) -> 7500
A25: TRANSFER OPERATING — fuel & supplies scale with the run count
A26: Truck Payment / Replacement Reserve | B26: $ / yr | C26: 10000 | D26: 15000 | E26: 30000 | F26: =CHOOSE(Scenarios!$H$2,C26,D26,E26) -> 15000
A27: Vehicle Maintenance (annual) | B27: $ / yr | C27: 10000 | D27: 12000 | E27: 30000 | F27: =CHOOSE(Scenarios!$H$2,C27,D27,E27) -> 12000
A28: Fuel Cost per Run | B28: $ / run | C28: =INDEX($E$45:$E$49,$H$4) -> 20 | D28: =INDEX($E$45:$E$49,$H$4) -> 20 | E28: =INDEX($E$45:$E$49,$H$4) -> 20 | F28: =CHOOSE(Scenarios!$H$2,C28,D28,E28) -> 20 | G28: Set PER CONFIGURATION in the fleet table below (CC hauls often go further)
A29: Fuel (runs × cost per run) | B29: $ / yr | C29: =C7*C28 -> 30000 | D29: =D7*D28 -> 30000 | E29: =E7*E28 -> 30000 | F29: =CHOOSE(Scenarios!$H$2,C29,D29,E29) -> 30000
A30: Medical Supplies per Run | B30: $ / run | C30: =INDEX($D$45:$D$49,$H$4) -> 60 | D30: =INDEX($D$45:$D$49,$H$4) -> 60 | E30: =INDEX($D$45:$D$49,$H$4) -> 60 | F30: =CHOOSE(Scenarios!$H$2,C30,D30,E30) -> 60 | G30: Set PER CONFIGURATION in the fleet table below — CC runs burn more supplies than BLS
A31: Medical Supplies (runs × cost per run) | B31: $ / yr | C31: =C7*C30 -> 90000 | D31: =D7*D30 -> 90000 | E31: =E7*E30 -> 90000 | F31: =CHOOSE(Scenarios!$H$2,C31,D31,E31) -> 90000
A32: Insurance | B32: $ / yr | C32: 0 | D32: 0 | E32: 0 | F32: =CHOOSE(Scenarios!$H$2,C32,D32,E32) -> 0 | G32: Already covered by the $21,100 policy on Details — only enter a premium INCREASE
A33: Other Transfer Cost 1 (rename me) | B33: $ / yr | C33: 0 | D33: 0 | E33: 0 | F33: =CHOOSE(Scenarios!$H$2,C33,D33,E33) -> 0
A34: Other Transfer Cost 2 (rename me) | B34: $ / yr | C34: 0 | D34: 0 | E34: 0 | F34: =CHOOSE(Scenarios!$H$2,C34,D34,E34) -> 0
A35: Other Transfer Cost 3 (rename me) | B35: $ / yr | C35: 0 | D35: 0 | E35: 0 | F35: =CHOOSE(Scenarios!$H$2,C35,D35,E35) -> 0
A36: SELECTED CONFIGURATION | B36: =$B$4&" — "&INDEX($B$45:$B$49,$H$4)&" · "&TEXT(INDEX($C$45:$C$49,$H$4),"$#,##0")&" / run" -> 2 Critical Care Trucks — 1 CC provider + 1 medic on each truck · $825 / run
A37: SUMMARY
A38: TOTAL TRANSFER REVENUE | B38: $ / yr | C38: =C10 -> 1237500 | D38: =D10 -> 1237500 | E38: =E10 -> 1237500 | F38: =CHOOSE(Scenarios!$H$2,C38,D38,E38) -> 1237500 | H38: =IF($B$3="OFF",0,CHOOSE(Scenarios!$H$2,C38,D38,E38)) -> 1237500
A39: TOTAL TRANSFER EXPENSES | B39: $ / yr | C39: =C11+C19+C20+C21+C22+C24+C26+C27+C29+C31+C32+SUM(C33:C35) -> 572811.43 | D39: =D11+D19+D20+D21+D22+D24+D26+D27+D29+D31+D32+SUM(D33:D35) -> 643864.36 | E39: =E11+E19+E20+E21+E22+E24+E26+E27+E29+E31+E32+SUM(E33:E35) -> 731229.57 | F39: =CHOOSE(Scenarios!$H$2,C39,D39,E39) -> 643864.36 | H39: =IF($B$3="OFF",0,CHOOSE(Scenarios!$H$2,C39,D39,E39)) -> 643864.36
A40: NET IMPACT ON BUDGET | B40: $ / yr | C40: =C38-C39 -> 664688.57 | D40: =D38-D39 -> 593635.64 | E40: =E38-E39 -> 506270.43 | F40: =CHOOSE(Scenarios!$H$2,C40,D40,E40) -> 593635.64
...

Sheet Change Log
A1: CHANGE LOG — write down every change you make
A2: Manual log — Excel alone cannot track users automatically or restrict deletes to one person. For automatic, undeletable per-user history: store this file on OneDrive/SharePoint (owner: Kenneth.James@millstadtems.org) and use File → Info → Version History and Review → Show Changes.
A4: DATE | B4: WHO | C4: TAB | D4: WHAT CHANGED | E4: OLD → NEW | F4: WHY
